Workbook
Name lifeprod_aec: 'Final specifications'!$B$17
Name lifeprod_pem: 'Final specifications'!$C$17
Name lifeprod_soec: 'Final specifications'!$D$17
Name lifetime_aec: 'Final specifications'!$B$7
Name lifetime_pem: 'Final specifications'!$C$7
Name lifetime_soec: 'Final specifications'!$D$7

Sheet readme
A1: skip
B3: This inventory has been taken from the additional premise inventories.
B5: https://github.com/polca/premise/tree/master/premise/data/additional_inventories
B7: It has been downloaded in April 2024.
B9: This inventory models hydrogen production from electrolysis with PEM, AEC and SOEC electrolysers.
B11: It contains the following datasets:
B13: =lci!B4 | C13: =lci!B185 | D13: =lci!B346
B14: =lci!B24 | C14: =lci!B206 | D14: =lci!B367
B15: =lci!B49 | C15: =lci!B223 | D15: =lci!B393
B16: =lci!B64 | C16: =lci!B235 | D16: =lci!B404
B17: =lci!B122 | C17: =lci!B304 | D17: =lci!B478
B18: =lci!B144

Sheet lci
A1: cutoff | B1: 9
A2: Database | B2: h2_electrolysis
A4: Activity | B4: hydrogen production, gaseous, 30 bar, from PEM electrolysis, from grid electricity
A5: production amount | B5: 1
A6: comment | B6: 1 kg H2 produced using a PEM electrolyzer. Original source: 1 MW PEM electrolyzer based on Niklas Gerloff, Comparative Life-Cycle-Assessment analysis of three major water electrolysis technologies while applying various energy scenarios for a greener hydrogen production, Journal of Energy Storage, Volume 43, 2021, https://doi.org/10.1016/j.est.2021.102759. Further refined (with respect to stack and system lifetime and water use, notably) from data from manufacturer's specifications (see tab "Manufacturers' data") and IndWEDe project report (https://www.now-gmbh.de/wp-content/uploads/2020/09/181127_bro_a4_indwede-studie_kurzfassung_de_v03.pdf). For further secifications (e.g., efficiency, lifetime, etc.), see tab "Final specifications".
A7: reference product | B7: hydrogen, gaseous, 30 bar
A8: location | B8: RER
A9: unit | B9: kilogram
A10: Exchanges
A11: name | B11: amount | C11: reference product | D11: location | E11: unit | F11: categories | G11: type | H11: database | I11: comment
A12: hydrogen production, gaseous, 30 bar, from PEM electrolysis, from grid electricity | B12: 1 | C12: hydrogen, gaseous, 30 bar | D12: RER | E12: kilogram | G12: production | H12: h2_electrolysis
A13: electrolyzer production, 1MWe, PEM, Stack | B13: 1.349892e-06 | C13: electrolyzer, 1MWe, PEM, Stack | D13: RER | E13: unit | G13: technosphere | H13: h2_electrolysis | I13: Stack, 5.5 years lifetime.
A14: electrolyzer production, 1MWe, PEM, Balance of Plant | B14: 3.37473e-07 | C14: electrolyzer, 1MWe, PEM, Balance of Plant | D14: RER | E14: unit | G14: technosphere | H14: h2_electrolysis | I14: BoP, 20 years lifetime.
A15: treatment of fuel cell stack, 1MWe, PEM | B15: -1.349892e-06 | C15: used fuel cell stack, 1MWe, PEM | D15: RER | E15: unit | G15: technosphere | H15: h2_electrolysis | I15: Stack EoL | K15: These columns have been used for something. But I don't want BW to read them in - they are not in the correct format for BW, but I still want to keep that information.
A16: treatment of fuel cell balance of plant, 1MWe, PEM | B16: -3.37473e-07 | C16: used fuel cell balance of plant, 1MWe, PEM | D16: RER | E16: unit | G16: technosphere | H16: h2_electrolysis | I16: BoP EoL | K16: In cell A1 and A2, I tell BW to ignore any column > 9 from the left.
A17: Electricity, low voltage, at grid | B17: 54 | C17: Electricity, low voltage, at grid | D17: RER | E17: kilowatt hour | G17: technosphere | H17: bafu | I17: Electricity consumption with 61.7% eff. | K17: Note that this has nothing to do with the system model "cut off" from ecoinvent.
A18: Water, deionised, at plant | B18: 14 | C18: Water, deionised, at plant | D18: CH | E18: kilogram | G18: technosphere | H18: bafu | I18: A perfect reaction of H2O results in 1 kg H2 and 8 kg O2, and needs 9 kg H2O, however, considering some losses we assume 14 kg H2O (Simoes et al., 2021).
A19: Oxygen | B19: 8 | E19: kilogram | F19: air | G19: biosphere | H19: biosphere3
A20: Occupation, industrial area | B20: 0.0006074514 | E20: square meter-year | F20: natural resource::land | G20: biosphere | H20: biosphere3 | I20: Electrolyser land footprint: (0.09 [m2/kW]*1000[kW/MW])/(2963200[kg H2 per lifetime]/20[years]) | K20: 2 | L20: -7.4062384 | M20: 1.05 | N20: 1.1 | O20: 1 | P20: 1.02 | Q20: 1.2 | R20: 1.2 | S20: 1.5 | T20: 0.24634372
A21: Transformation, from industrial area | B21: 3.037257e-05 | E21: square meter | F21: natural resource::land | G21: biosphere | H21: biosphere3 | I21: Electrolyser land transformation: (0.09 [m2/kW]*1000 [kW/MW])/2963200 [kg H2] | K21: 2 | L21: -10.401971 | M21: 1.05 | N21: 1.1 | O21: 1 | P21: 1.02 | Q21: 1.2 | R21: 1.2 | S21: 1.5 | T21: 0.24634372
A22: Transformation, to industrial area | B22: 3.037257e-05 | E22: square meter | F22: natural resource::land | G22: biosphere | H22: biosphere3 | I22: Electrolyser land transformation: (0.09 [m2/kW]*1000 [kW/MW])/2963200 [kg H2] | K22: 2 | L22: -10.401971 | M22: 1.05 | N22: 1.1 | O22: 1 | P22: 1.02 | Q22: 1.2 | R22: 1.2 | S22: 1.5 | T22: 0.24634372
A24: Activity | B24: electrolyzer production, 1MWe, PEM, Stack
A25: production amount | B25: 1
A26: comment | B26: 1 MW PEM electrolyzer based on Niklas Gerloff, Comparative Life-Cycle-Assessment analysis of three major water electrolysis technologies while applying various energy scenarios for a greener hydrogen production, Journal of Energy Storage, Volume 43, 2021, https://doi.org/10.1016/j.est.2021.102759. Lifetime of 7-8 years per single stack, @ 8000 hours/year. Iridium mining process is NOT from ecoinvent. Produced amount of H2 over 20 years: 2964315.35 kg. According to a study called IndWEDe, it is assumed that the stacks are replaced 3 times during the 20 years lifespan, based on the 2030’s scenario for 1 MW systems which predicts a lifetime of 50,000 h or more for the stacks of the different water electrolysis technologies. In comparison to AEC electrolyzers, PEMEC electrolyzers are less mature. Furthermore, the PEMEC technology is commercially available and operates with a similar system efficiency as the AEC technology. However, the current density and the gas purity are higher with values in between 0.6–2.0 A/cm2 and > 99.99%, respectively. Besides this, the operating pressure (below 200 bar) is significantly higher in comparison to AEC systems, while the operating temperature (50 °C to 80 °C) and the system energy (4.2–6.6 kWh/m3H2) are similar to AEC systems. The PEMEC BoP and stack components data stem from Bareiß et al. and correspond to a 1 MW system. Moreover, some further BoP components like water purifier & feed tank, buffer tank, and heat exchanger have been added, derived from a 300 kW AEC system, under the assumption that the components are also suitable for a PEMEC system. The values have been scaled up from 300 kW to 1 MW. Values have already been multiplied by 3 to reflect 2 stack replacements over 20 years of use.
A27: reference product | B27: electrolyzer, 1MWe, PEM, Stack
A28: location | B28: RER
A29: unit | B29: unit
A30: Exchanges
A31: name | B31: amount | C31: reference product | D31: location | E31: unit | F31: categories | G31: type | H31: database | I31: comment
A32: electrolyzer production, 1MWe, PEM, Stack | B32: 1 | C32: electrolyzer, 1MWe, PEM, Stack | D32: RER | E32: unit | G32: production | H32: h2_electrolysis
A33: Aluminium, production mix, wrought alloy, at plant | B33: 27 | C33: Aluminium, production mix, wrought alloy, at plant | D33: RER | E33: kilogram | G33: technosphere | H33: bafu | I33: end plate
A34: Sheet rolling, aluminium | B34: 27 | C34: Sheet rolling, aluminium | D34: RER | E34: kilogram | G34: technosphere | H34: bafu | I34: end plate
A35: Titanium dioxide, production mix, at plant | B35: 528 | C35: Titanium dioxide, production mix, at plant | D35: RER | E35: kilogram | G35: technosphere | H35: bafu | I35: bipolar plate
A36: Tetrafluoroethylene, at plant | B36: 16 | C36: Tetrafluoroethylene, at plant | D36: RER | E36: kilogram | G36: technosphere | H36: bafu | I36: membrane polymer
A37: Carbon black, at plant | B37: 4.5 | C37: Carbon black, at plant | D37: GLO | E37: kilogram | G37: technosphere | H37: bafu | I37: electrocatalyst anode
A38: iridium production | B38: 0.8 | C38: iridium | D38: GLO | E38: kilogram | G38: technosphere | H38: h2_electrolysis | I38: electrocatalyst anode
A39: Platinum, at regional storage | B39: 0.075 | C39: Platinum, at regional storage | D39: RER | E39: kilogram | G39: technosphere | H39: bafu | I39: electrocatalyst cathode
A40: Carbon black, at plant | B40: 4.5 | C40: Carbon black, at plant | D40: GLO | E40: kilogram | G40: technosphere | H40: bafu | I40: electrocatalyst cathode
A41: Copper, primary, at refinery | B41: 4.5 | C41: Copper, primary, at refinery | D41: GLO | E41: kilogram | G41: technosphere | H41: bafu | I41: current collector
A42: Sheet rolling, copper | B42: 4.5 | C42: Sheet rolling, copper | D42: RER | E42: kilogram | G42: technosphere | H42: bafu | I42: current collector
...

Sheet Final specifications
A1: skip
B3: AEC | C3: PEMC | D3: SOEC | E3: SOEC + steam | F3: Source
A4: Stack lifetime [hours] | B4: 55’000 | C4: 45’000 | D4: 20’000 | F4: IndWEDe
A5: Stack lifetime [years] | B5: 7 | C5: 5.5 | D5: 2.5 | F5: IndWEDe, based on the lower estimate of 8,000 hours per year, from manufacturers’ data.
A6: Balance of Plant lifetime [years] | B6: Same as system. | F6: From row below.
A7: System lifetime [years] | B7: 27.5 | C7: 20 | D7: 20 | F7: IndWEDe
A8: Stack replacement over system’s lifetime, excluding initial unit [unit] | B8: 3 | C8: 3 | D8: 7 | F8: Calculated.
A9: Water demand [kg water/kg H2] | B9: 8.9, corrected to 14 to represent “real world” operation. | F9: (Simoes et al. 2021)
A10: Electricity demand [kWh/kg H2] | B10: 51.8 | C10: 54 | D10: 42.3 | E10: 39 | F10: IndWEDe for all cases, except SOEC + steam, which is based on manufacturers’ data.
A11: Electrical Efficiency [%, based on H2 LHV] | B11: 0.645 | C11: 0.617 | D11: 0.787 | E11: 0.85 | F11: From row above.
A12: Steam demand [kWh/kg H2] | E12: 16 | F12: Manufacturers’ data, also matching with (Gerloff 2021a).
A13: Productivity [kg H2/hour] | B13: 19.36 | C13: 18.52 | D13: 23.6 | F13: From row above.
A14: KOH [kg/kg H2] | B14: 0.0037 | F14: (Gerloff 2021a)
A15: Operating temperature [°C] | B15: 60-80 | C15: 50-80 | D15: 650-1000 | F15: Manufacturers’ data.
A16: Operating pressure [bar] | B16: ~20 | C16: ~30 | D16: ~1 | F16: IndWEDe
A17: Produced amount over system’s lifetime years [kg H2] | B17: 4259200 | C17: 2963200 | D17: 3776000 | F17: Calculated based on the system’s lifetime (fourth row), and 8,000 hours stack operation per year (from manufacturers’ data) and hourly productivity.

Sheet Manufacturers' data
A1: skip
A3: Manufacturer | B3: Model | C3: Electrolysis type | D3: Minimum power consumption [kW] | E3: Rated power [kW] | F3: Maximum power consumption [kW] | G3: Voltage consumption [V] | H3: Type of current [V] | I3: Space requirement [m²/kW] | J3: Start-up dynamics [s] | K3: Water treatment [s] | L3: Max. system availability [hours/year] | M3: Min. ambient temperature [°C] | N3: Max. Ambient temperature [°C] | O3: Spec. electricity demand [kWh/Nm³H2] | P3: Spec. electricity demand [kWh/kgH2] | Q3: Spec. Heat demand [MJ/kgH2] | R3: Useful heat output [kW/kW] | S3: Temperature of useful heat [°C] | T3: Electrical efficiency [%, LHV] | U3: Total efficiency [%] | V3: Minimum stack temperature [°C] | W3: Maximum stack temperature [°C] | X3: Required water quality [µS/cm] | Y3: Stack life [h] | Z3: Maintenance interval [h] | AA3: H2 quality | AB3: H2 pressure level [bar] | AC3: H2 quantity [kg/h] | AD3: H2 quantity [Nm³/h] | AE3: Gas treatment | AF3: H2 quality after treatment | AG3: Maximum H2 pressure level [bar]
A4: Hoeller Electrolyzer_x000D_GmbH | B4: Prometheus L_x000D_Stack | C4: PEM | D4: 300 | E4: 1500 | F4: 1800 | G4: 616 | H4: DC | J4: 10 | K4: Yes | O4: 4.85 | P4: =((1000*O4)/0.08924)/1000 | T4: 61.9 | V4: 5 | W4: 80 | X4: 0.1 | Y4: 80000 | AA4: 5.5 | AB4: 40 | AC4: 27.8 | AD4: 308.9 | AE4: Optional
A5: HIAT gGmbH | B5: PURIFIER | C5: PEM | F5: 2 | O5: 5 | P5: =((1000*O5)/0.08924)/1000 | T5: 60 | V5: 20 | W5: 80 | X5: 0.1 | Y5: 40000 | AB5: 40 | AC5: 0.05 | AD5: 0.6
A6: Enapter | B6: EL 2.1 | C6: AEC | F6: 2.4 | G6: 230 | H6: AC | I6: 0.125 | J6: 3 | K6: Optional | M6: 5 | N6: 45 | O6: 4.8 | P6: =((1000*O6)/0.08924)/1000 | T6: 62.5 | V6: 20 | W6: 55 | X6: 20 | Y6: 30000 | AA6: 3 | AB6: 35 | AC6: 0.45 | AD6: 5 | AE6: Optional
A7: McPhy Energy S.A. | B7: Piel Baby | C7: AEC | F7: 3 | AB7: 1 | AC7: 0.04 | AD7: 0.4 | AE7: Optional
A8: ostermeier H2ydrogen_x000D_Solutions GmbH | B8: EO.05 | C8: PEM | D8: 1 | E8: 6 | F8: 7 | G8: 400 | H8: AC | I8: 0.42857143 | J8: 40 | K8: Yes | L8: 8500 | M8: 5 | N8: 35 | V8: 20 | W8: 65 | X8: 0.1 | Y8: 35000 | AA8: 3 | AB8: 20 | AC8: 0.1 | AD8: 1.1 | AE8: Optional
A9: McPhy Energy S.A. | B9: Piel P | C9: AEC | D9: 6 | F9: 9 | AB9: 2.5 | AC9: 0.14 | AD9: 1.6 | AE9: Optional
A10: H2 Core Systems GmbH | B10: HydroCab_x000D_Indoor 2.0_x000D_Nm3/h | C10: AEC | D10: 1 | E10: 10 | F10: 10 | G10: 400 | H10: AC/_x000D_DC | I10: 0.1 | J10: 3 | K10: Optional | L10: 8700 | M10: 5 | N10: 40 | O10: 4.8 | P10: =((1000*O10)/0.08924)/1000 | R10: 0.2 | T10: 62.5 | U10: 92.5 | V10: 20 | W10: 55 | X10: 2 | Y10: 35000 | Z10: 8760 | AA10: 3 | AB10: 35 | AC10: 0.18 | AD10: 2 | AE10: Optional | AF10: 5 | AG10: 35
A11: H2 Core Systems GmbH | B11: HydroCab_x000D_Outdoor 2.0_x000D_Nm3/h | C11: AEC | D11: 1 | E11: 10 | F11: 10 | G11: 400 | H11: AC/_x000D_DC | I11: 0.1 | J11: 3 | K11: Optional | L11: 8700 | M11: -25 | N11: 40 | O11: 4.8 | P11: =((1000*O11)/0.08924)/1000 | R11: 0.2 | T11: 62.5 | U11: 92.5 | V11: 20 | W11: 55 | X11: 2 | Y11: 35000 | Z11: 8760 | AA11: 3 | AB11: 35 | AC11: 0.18 | AD11: 2 | AE11: Optional | AF11: 5 | AG11: 35
A12: HIAT gGmbH | B12: CUSTOMIZER | C12: PEM | F12: 13 | O12: 5 | P12: =((1000*O12)/0.08924)/1000 | T12: 60 | V12: 20 | W12: 80 | X12: 0.1 | Y12: 40000 | AB12: 40 | AC12: 0.23 | AD12: 2.5
A13: ostermeier H2ydrogen_x000D_Solutions GmbH | B13: EO.10 | C13: PEM | D13: 1 | E13: 11 | F13: 14 | G13: 400 | H13: AC | I13: 0.21428571 | J13: 40 | K13: Yes | L13: 8500 | M13: 5 | N13: 35 | V13: 20 | W13: 65 | X13: 0.1 | Y13: 35000 | AA13: 3 | AB13: 20 | AC13: 0.2 | AD13: 2.2 | AE13: Optional
A14: ostermeier H2ydrogen_x000D_Solutions GmbH | B14: EO.15 | C14: PEM | D14: 1 | E14: 17 | F14: 20 | G14: 400 | H14: AC | I14: 0.15 | J14: 40 | K14: Yes | L14: 8500 | M14: 5 | N14: 35 | V14: 20 | W14: 65 | X14: 0.1 | Y14: 35000 | AA14: 3 | AB14: 20 | AC14: 0.3 | AD14: 3.3 | AE14: Optional
A15: H2 Core Systems GmbH | B15: HydroCab_x000D_Indoor 4.5_x000D_Nm3/h | C15: AEC | D15: 1 | E15: 22 | F15: 22 | G15: 400 | H15: AC/_x000D_DC | I15: 0.090909091 | J15: 3 | K15: Optional | L15: 8700 | M15: 5 | N15: 45 | O15: 4.8 | P15: =((1000*O15)/0.08924)/1000 | R15: 0.22727273 | T15: 62.5 | U15: 92.5 | V15: 20 | W15: 55 | X15: 2 | Y15: 35000 | Z15: 8760 | AA15: 3 | AB15: 35 | AC15: 0.4 | AD15: 4.4 | AE15: Optional | AF15: 5 | AG15: 35
A16: H2 Core Systems GmbH | B16: HydroCab_x000D_Outdoor 4.5_x000D_Nm3/h | C16: AEC | D16: 1 | E16: 22 | F16: 22 | G16: 400 | H16: AC/_x000D_DC | I16: 0.090909091 | J16: 3 | K16: Optional | L16: 8700 | M16: -25 | N16: 40 | O16: 4.8 | P16: =((1000*O16)/0.08924)/1000 | R16: 0.22727273 | T16: 62.5 | U16: 92.5 | V16: 20 | W16: 55 | X16: 2 | Y16: 35000 | Z16: 8760 | AA16: 3 | AB16: 35 | AC16: 0.4 | AD16: 4.4 | AE16: Optional | AF16: 5 | AG16: 35
A17: McPhy Energy S.A. | B17: Piel M | C17: AEC | D17: 14 | F17: 26 | AB17: 2.5 | AC17: 0.4 | AD17: 4.4 | AE17: Optional
A18: ostermeier H2ydrogen_x000D_Solutions GmbH | B18: EO.20 | C18: PEM | D18: 1 | E18: 22 | F18: 27 | G18: 400 | H18: AC | I18: 0.11111111 | J18: 40 | K18: Yes | L18: 8500 | M18: 5 | N18: 35 | V18: 20 | W18: 65 | X18: 0.1 | Y18: 35000 | AA18: 3 | AB18: 20 | AC18: 0.4 | AD18: 4.4 | AE18: Optional
A19: AVX/KUMATEC Hydrogen_x000D_GmbH & Co. KG | B19: PEM-100-25 | C19: PEM | D19: 3 | E19: 25 | F19: 28 | G19: 400 | H19: AC | I19: 0.53571429 | J19: 1 | K19: Yes | L19: 8410 | M19: -20 | N19: 40 | O19: 4.9 | P19: =((1000*O19)/0.08924)/1000 | T19: 61.2 | V19: 20 | W19: 80 | X19: 1 | Y19: 50000 | AA19: 3.5 | AB19: 100 | AC19: 0.45 | AD19: 5 | AE19: Yes
A20: ostermeier H2ydrogen_x000D_Solutions GmbH | B20: EO.25 | C20: PEM | D20: 1 | E20: 27 | F20: 33 | G20: 400 | H20: AC | I20: 0.090909091 | J20: 40 | K20: Yes | L20: 8500 | M20: 5 | N20: 35 | V20: 20 | W20: 65 | X20: 0.1 | Y20: 35000 | AA20: 3 | AB20: 20 | AC20: 0.5 | AD20: 5.6 | AE20: Optional
A21: HIAT gGmbH | B21: SUPPLIER | C21: PEM | F21: 35 | O21: 5 | P21: =((1000*O21)/0.08924)/1000 | T21: 60 | V21: 20 | W21: 80 | X21: 0.1 | Y21: 40000 | AB21: 40 | AC21: 0.63 | AD21: 6.9
A22: H2 Core Systems GmbH | B22: HydroCab_x000D_Indoor 9.0_x000D_Nm3/h | C22: AEC | D22: 1 | E22: 43 | F22: 43 | G22: 400 | H22: AC/_x000D_DC | I22: 0.093023256 | J22: 3 | K22: Optional | L22: 8700 | M22: 5 | N22: 45 | O22: 4.8 | P22: =((1000*O22)/0.08924)/1000 | R22: 0.25581395 | T22: 62.5 | U22: 92.5 | V22: 20 | W22: 55 | X22: 2 | Y22: 35000 | Z22: 8760 | AA22: 3 | AB22: 35 | AC22: 0.8 | AD22: 8.9 | AE22: Optional | AF22: 5 | AG22: 35
A23: H2 Core Systems GmbH | B23: HydroCab_x000D_Outdoor 9.0_x000D_Nm3/h | C23: AEC | D23: 1 | E23: 43 | F23: 43 | G23: 400 | H23: AC/_x000D_DC | I23: 0.093023256 | J23: 3 | K23: Optional | L23: 8700 | M23: -25 | N23: 40 | O23: 4.8 | P23: =((1000*O23)/0.08924)/1000 | R23: 0.25581395 | T23: 62.5 | U23: 92.5 | V23: 20 | W23: 55 | X23: 2 | Y23: 35000 | Z23: 8760 | AA23: 3 | AB23: 35 | AC23: 0.8 | AD23: 8.9 | AE23: Optional | AF23: 5 | AG23: 35
A24: McPhy Energy S.A. | B24: McLyzer 10-30 | C24: AEC | F24: 50 | H24: DC | O24: 4.5 | P24: =((1000*O24)/0.08924)/1000 | T24: 66.7 | AB24: 30 | AC24: 0.9 | AD24: 10
A25: Kyros Hydrogen_x000D_Solutions GmbH | B25: Kyros_x000D_Electrolyzer 50 | C25: PEM | D25: 10 | E25: 50 | F25: 60 | G25: 400 | H25: AC/_x000D_DC | I25: 0.11666667 | J25: 15 | K25: Yes | L25: 8650 | M25: -40 | N25: 35 | O25: 4.8 | P25: =((1000*O25)/0.08924)/1000 | R25: 0.16666667 | S25: 62 | T25: 62.5 | V25: 25 | W25: 75 | X25: 0.1 | Y25: 80000 | Z25: 8600 | AA25: 3.8 | AB25: 40 | AC25: 0.89 | AD25: 9.9 | AE25: Yes | AF25: 5 | AG25: 40
A26: McPhy Energy S.A. | B26: Piel H | C26: AEC | D26: 18 | F26: 60 | AB26: 8 | AC26: 0.9 | AD26: 10 | AE26: Optional
A27: H2 Core Systems GmbH | B27: HydroCab_x000D_Indoor 18.0_x000D_Nm3/h | C27: AEC | D27: 1 | E27: 86 | F27: 86 | G27: 400 | H27: AC/_x000D_DC | I27: 0.093023256 | J27: 3 | K27: Optional | L27: 8700 | M27: 5 | N27: 45 | O27: 4.8 | P27: =((1000*O27)/0.08924)/1000 | R27: 0.25581395 | T27: 62.5 | U27: 92.5 | V27: 20 | W27: 55 | X27: 2 | Y27: 35000 | Z27: 8760 | AA27: 3 | AB27: 35 | AC27: 1.6 | AD27: 17.8 | AE27: Optional | AF27: 5 | AG27: 35
A28: H2 Core Systems GmbH | B28: HydroCab_x000D_Outdoor 18.0_x000D_Nm3/h | C28: AEC | D28: 1 | E28: 86 | F28: 86 | G28: 400 | H28: AC/_x000D_DC | I28: 0.093023256 | J28: 3 | K28: Optional | L28: 8700 | M28: -25 | N28: 40 | O28: 4.8 | P28: =((1000*O28)/0.08924)/1000 | R28: 0.25581395 | T28: 62.5 | U28: 92.5 | V28: 20 | W28: 55 | X28: 2 | Y28: 35000 | Z28: 8760 | AA28: 3 | AB28: 35 | AC28: 1.6 | AD28: 17.8 | AE28: Optional | AF28: 5 | AG28: 35
A29: McPhy Energy S.A. | B29: McLyzer 20-30 | C29: AEC | F29: 100 | H29: DC | O29: 4.5 | P29: =((1000*O29)/0.08924)/1000 | T29: 66.7 | AB29: 30 | AC29: 1.8 | AD29: 20
A30: HIAT gGmbH | B30: STORAGER | C30: PEM | F30: 100 | O30: 5 | P30: =((1000*O30)/0.08924)/1000 | T30: 60 | V30: 20 | W30: 80 | X30: 0.1 | Y30: 40000 | AB30: 40 | AC30: 1.79 | AD30: 19.9
A31: iph Hähn Gmbh | B31: EL20 | C31: PEM | D31: 12 | E31: 100 | F31: 105 | G31: 400 | H31: AC | I31: 0.066666667 | J31: 40 | K31: Optional | L31: 8600 | M31: 5 | N31: 45 | AB31: 30 | AC31: 1.75 | AD31: 19.4 | AE31: Optional
A32: AVX/KUMATEC Hydrogen_x000D_GmbH & Co. KG | B32: PEM-40-100 | C32: PEM | D32: 10 | E32: 100 | F32: 110 | G32: 400 | H32: AC | I32: 0.13636364 | J32: 1 | K32: Yes | L32: 8410 | M32: -20 | N32: 40 | O32: 4.67 | P32: =((1000*O32)/0.08924)/1000 | T32: 64.2 | V32: 5 | W32: 70 | X32: 1 | Y32: 80000 | AA32: 3.5 | AB32: 40 | AC32: 1.8 | AD32: 20 | AE32: Yes
A33: Hydrogenics_x000D_(Cummins Inc.)* | B33: HySTAT 10 | C33: AEC | D33: 46 | F33: 115 | H33: AC | I33: 0.46956522 | K33: Yes | M33: -20 | N33: 40 | O33: 4.9 | P33: =((1000*O33)/0.08924)/1000 | AA33: 4.8 | AB33: 10 | AC33: 0.88 | AD33: 9.7 | AE33: Yes
A34: Kyros Hydrogen_x000D_Solutions GmbH | B34: Kyros_x000D_Electrolyzer 100 | C34: PEM | D34: 20 | E34: 100 | F34: 120 | G34: 400 | H34: AC/_x000D_DC | I34: 0.058333333 | J34: 15 | K34: Yes | L34: 8650 | M34: -40 | N34: 35 | O34: 4.8 | P34: =((1000*O34)/0.08924)/1000 | R34: 0.16666667 | S34: 62 | T34: 62.5 | V34: 25 | W34: 75 | X34: 0.1 | Y34: 80000 | Z34: 8600 | AA34: 3.8 | AB34: 40 | AC34: 1.78 | AD34: 19.8 | AE34: Yes | AF34: 5 | AG34: 40
A35: Hoeller Electrolyzer_x000D_GmbH | B35: Prometheus S_x000D_Stack | C35: PEM | D35: 21 | E35: 100 | F35: 120 | G35: 300 | H35: DC | J35: 10 | K35: Yes | O35: 4.83 | P35: =((1000*O35)/0.08924)/1000 | T35: 62.1 | V35: 5 | W35: 80 | X35: 0.1 | Y35: 80000 | AA35: 5.5 | AB35: 40 | AC35: 1.9 | AD35: 21.1 | AE35: Optional
A36: Hydrogenics_x000D_(Cummins Inc.)* | B36: HySTAT 15 | C36: AEC | D36: 62 | F36: 155 | H36: AC | I36: 0.3483871 | K36: Yes | M36: -20 | N36: 40 | O36: 4.9 | P36: =((1000*O36)/0.08924)/1000 | AA36: 4.8 | AB36: 10 | AC36: 1.33 | AD36: 14.8 | AE36: Yes
A37: H2 Core Systems GmbH | B37: HydroCab_x000D_Indoor 36.0_x000D_Nm3/h | C37: AEC | D37: 1 | E37: 173 | F37: 173 | G37: 400 | H37: AC/_x000D_DC | I37: 0.092485549 | J37: 3 | K37: Optional | L37: 8700 | M37: 5 | N37: 45 | O37: 4.8 | P37: =((1000*O37)/0.08924)/1000 | R37: 0.24855491 | T37: 62.5 | U37: 92.5 | V37: 20 | W37: 55 | X37: 2 | Y37: 35000 | Z37: 8760 | AA37: 3 | AB37: 35 | AC37: 3.2 | AD37: 35.6 | AE37: Optional | AF37: 5 | AG37: 35
A38: H2 Core Systems GmbH | B38: HydroCab_x000D_Outdoor 36.0_x000D_Nm3/h | C38: AEC | D38: 1 | E38: 173 | F38: 173 | G38: 400 | H38: AC/_x000D_DC | I38: 0.092485549 | J38: 3 | K38: Optional | L38: 8700 | M38: -25 | N38: 40 | O38: 4.8 | P38: =((1000*O38)/0.08924)/1000 | R38: 0.24855491 | T38: 62.5 | U38: 92.5 | V38: 20 | W38: 55 | X38: 2 | Y38: 35000 | Z38: 8760 | AA38: 3 | AB38: 35 | AC38: 3.2 | AD38: 35.6 | AE38: Optional | AF38: 5 | AG38: 35
A39: Kyros Hydrogen_x000D_Solutions GmbH | B39: Kyros_x000D_Electrolyzer 150 | C39: PEM | D39: 30 | E39: 150 | F39: 180 | G39: 400 | H39: AC/_x000D_DC | I39: 0.15555556 | J39: 15 | K39: Yes | L39: 8650 | M39: -40 | N39: 35 | O39: 4.8 | P39: =((1000*O39)/0.08924)/1000 | R39: 0.16666667 | S39: 62 | T39: 62.5 | V39: 25 | W39: 75 | X39: 0.1 | Y39: 80000 | Z39: 8600 | AA39: 3.8 | AB39: 40 | AC39: 2.67 | AD39: 29.7 | AE39: Yes | AF39: 5 | AG39: 40
A40: iph Hähn Gmbh | B40: EL40 | C40: PEM | D40: 24 | E40: 200 | F40: 210 | G40: 400 | H40: AC | I40: 0.066666667 | J40: 40 | K40: Optional | L40: 8600 | M40: 5 | N40: 45 | AB40: 30 | AC40: 3.5 | AD40: 38.9 | AE40: Optional
A41: Kyros Hydrogen_x000D_Solutions GmbH | B41: Kyros_x000D_Electrolyzer 200 | C41: PEM | D41: 20 | E41: 200 | F41: 240 | G41: 400 | H41: AC/_x000D_DC | I41: 0.058333333 | J41: 15 | K41: Optional | L41: 8650 | M41: -40 | N41: 35 | O41: 4.8 | P41: =((1000*O41)/0.08924)/1000 | R41: 0.16666667 | S41: 62 | T41: 62.5 | V41: 25 | W41: 75 | X41: 0.1 | Y41: 80000 | Z41: 8600 | AA41: 3.8 | AB41: 40 | AC41: 3.56 | AD41: 39.6 | AE41: Yes | AF41: 5 | AG41: 40
...
